Workbook

Sheet S1  Pathogen list and treshold
A1: taxID | B1: Krakenuniq name | C1: min_escore | D1: min_reads | E1: Guellil_et_al_Evalue_threshold
A2: 666 | B2: Vibrio cholerae | C2: 5 | D2: 50 | E2: 0.001
A3: 1211 | B3: Ungulate erythroparvovirus 1 | C3: 5 | D3: 5 | E3: 0.001
A4: 633 | B4: Yersinia pseudotuberculosis | C4: 5 | D4: 50 | E4: 0.001
A5: 28871 | B5: Taterapox virus | C5: 5 | D5: 1 | E5: 0.001
A6: 10255 | B6: Variola virus | C6: 5 | D6: 1 | E6: 0.001
A7: 10244 | B7: Monkeypox virus | C7: 5 | D7: 5 | E7: 0.001
A8: 10243 | B8: Cowpox virus | C8: 5 | D8: 5 | E8: 0.001
A9: 10245 | B9: Vaccinia virus | C9: 5 | D9: 5 | E9: 0.001
A10: 35794 | B10: Rickettsia slovaca | C10: 5 | D10: 50 | E10: 0.001
A11: 35790 | B11: Rickettsia japonica | C11: 5 | D11: 50 | E11: 0.001
A12: 1679933 | B12: Rattus norvegicus polyomavirus 1 | C12: 5 | D12: 1 | E12: 0.001
A13: 34105 | B13: Streptobacillus moniliformis | C13: 5 | D13: 50 | E13: 0.001
... A172: 35788 | B172: Rickettsia africae | C172: 5 | D172: 50 | E172: 0.001

Sheet S2  Sequencing Data
A1: sample | B1: library | C1: udg_treatment | D1: Raw reads
A2: LL155 | B2: LL155-P-MEX1-UDG1-6-30-PCR1 | C2: full | D2: 27617492
A3: LL157 | B3: LL157-P-MEX1-UDG1-6-32-PCR1 | C3: full | D3: 5051455
A4: LL158 | B4: LL158-P-MEX1-UDG1-6-33-PCR1 | C4: full | D4: 5564287
A5: LL159 | B5: LL159-P-MEX1-UDG1-6-34-PCR1 | C5: full | D5: 6045415
A6: LL160 | B6: LL160-P-MEX1-UDG1-6-35-PCR1 | C6: full | D6: 9434889
A7: LL161 | B7: LL161-P-MEX1-UDG1-6-36-PCR1 | C7: full | D7: 6242254
A8: LL163 | B8: LL163-P-MEX1-UDG1-7-38-PCR1 | C8: full | D8: 9386578
A9: LL066 | B9: LL066-A-MBEX1-PUDG1-1_10_S76_R1_001 | C9: partial | D9: 44218087
A10: LL066 | B10: LL066-A-MBEX1-PUDG1-1_11_S77_R1_001 | C10: partial | D10: 38899273
A11: LL066 | B11: LL066-A-MBEX1-PUDG1-1_12_S78_R1_001 | C11: partial | D11: 23796583
A12: LL066 | B12: LL066-A-MBEX1-PUDG1-1_1_S68_R1_001 | C12: partial | D12: 14965812
A13: LL066 | B13: LL066-A-MBEX1-PUDG1-1_2_S69_R1_001 | C13: partial | D13: 28995535
... A354: LL154 | B354: LL154-P-MEX1-NUDG1-62-102-PCR2 | C354: none | D354: 5715064

Sheet S3  Pathogens Hits simulated da
A1: Sample | B1: Pathogen | C1: Host_best_species | D1: Host_aligner | E1: Pathogen_screening_only | F1: Krakenuniq_reads | G1: Escore | H1: Guellil_et_al_Evalue | I1: Detected_by_Krakenuniq | J1: HOPS_score | K1: Detected_by_HOPS | L1: Mapped_reads | M1: Read_mapping_ratio | N1: Coverage | O1: Evenness | P1: Read_length_mean | Q1: Read_length_median | R1: Damage_5p_CtoT | S1: Relative_entropy | T1: Breadth_ratio | U1: ANI | V1: Edit_distance_decay_quality | W1: Edit_distance_decay_quality_default | X1: Genus_ranking | Y1: Score | Z1: Criteria_passed | AA1: Relative_entropy_100bp | AB1: Relative_entropy_1000bp
A2: Brucella_melitensis__tier2_low__345reads | B2: Brucella melitensis | D2: bowtie2 | E2: TRUE | F2: 29 | G2: 13.856191 | H2: 0.013328276 | I2: TRUE | J2: 0 | K2: FALSE | L2: 357 | M2: 12.3103 | N2: 0.0064X | O2: 0.64% | P2: 59.39 | Q2: 59 | R2: 0.126126 | S2: 0.707 | T2: 0.9959 | U2: 99.31% | V2: 0.8644 | W2: 0.8582 | X2: #1 | Y2: 9/10 | Z2: E-value > 0.001, Reads >= 20, ANI > 96.5%, 5' C>T Damage >= 0.01, Breadth Ratio >= 0.8, Edit distance damaged >= 0.5, Edit distance default (non-damaged) >= 0.6, Genus Ranking = 1, Read Mapping Ratio >= 0.5 | AA2: 0.5527 | AB2: 0.707
A3: Brucella_melitensis__tier3_low_mid__1491reads | B3: Brucella melitensis | D3: bowtie2 | E3: TRUE | F3: 105 | G3: 14.808267 | H3: 0.053712838 | I3: TRUE | J3: 0 | K3: FALSE | L3: 1404 | M3: 13.3714 | N3: 0.0262X | O3: 2.59% | P3: 61.57 | Q3: 61 | R3: 0.152455 | S3: 0.8514 | T3: 1.0016 | U3: 99.40% | V3: 0.8785 | W3: 0.873 | X3: #1 | Y3: 10/10 | Z3: E-value > 0.001, Reads >= 20, ANI > 96.5%, 5' C>T Damage >= 0.01, Breadth Ratio >= 0.8, Entropy (1000bp) >= 0.8 (bacteria), Edit distance damaged >= 0.5, Edit distance default (non-damaged) >= 0.6, Genus Ranking = 1, Read Mapping Ratio >= 0.5 | AA3: 0.6783 | AB3: 0.8514
A4: Brucella_melitensis__tier4_mid__6438reads | B4: Brucella melitensis | D4: bowtie2 | E4: TRUE | F4: 376 | G4: 15.900506 | H4: 0.20209681 | I4: TRUE | J4: 0 | K4: FALSE | L4: 5899 | M4: 15.6888 | N4: 0.1122X | O4: 10.66% | P4: 62.65 | Q4: 62 | R4: 0.168532 | S4: 0.9591 | T4: 1.0047 | U4: 99.43% | V4: 0.871 | W4: 0.8756 | X4: #1 | Y4: 10/10 | Z4: E-value > 0.001, Reads >= 20, ANI > 96.5%, 5' C>T Damage >= 0.01, Breadth Ratio >= 0.8, Entropy (1000bp) >= 0.8 (bacteria), Edit distance damaged >= 0.5, Edit distance default (non-damaged) >= 0.6, Genus Ranking = 1, Read Mapping Ratio >= 0.5 | AA4: 0.8168 | AB4: 0.9591
A5: Brucella_melitensis__tier4_mid__6438reads | B5: Brucella suis | D5: bowtie2 | E5: TRUE | F5: 26 | G5: 5.8932896 | H5: 0.0018354115 | I5: TRUE | J5: 0 | K5: FALSE | L5: 5637 | M5: 216.8077 | N5: 0.1066X | O5: 10.15% | P5: 62.72 | Q5: 62 | R5: 0.160445 | S5: 0.9572 | T5: 1.0037 | U5: 99.28% | V5: 0.8638 | W5: 0.8581 | X5: #3 | Y5: 9/10 | Z5: E-value > 0.001, Reads >= 20, ANI > 96.5%, 5' C>T Damage >= 0.01, Breadth Ratio >= 0.8, Entropy (1000bp) >= 0.8 (bacteria), Edit distance damaged >= 0.5, Edit distance default (non-damaged) >= 0.6, Read Mapping Ratio >= 0.5 | AA5: 0.8131 | AB5: 0.9572
A6: Brucella_melitensis__tier5_mid_high__27795reads | B6: Brucella melitensis | D6: bowtie2 | E6: TRUE | F6: 1744 | G6: 16.938412 | H6: 0.71879782 | I6: TRUE | J6: 0 | K6: FALSE | L6: 25237 | M6: 14.4708 | N6: 0.4813X | O6: 38.09% | P6: 62.84 | Q6: 62 | R6: 0.168855 | S6: 0.99 | T6: 0.9971 | U6: 99.43% | V6: 0.8724 | W6: 0.8763 | X6: #1 | Y6: 10/10 | Z6: E-value > 0.001, Reads >= 20, ANI > 96.5%, 5' C>T Damage >= 0.01, Breadth Ratio >= 0.8, Entropy (1000bp) >= 0.8 (bacteria), Edit distance damaged >= 0.5, Edit distance default (non-damaged) >= 0.6, Genus Ranking = 1, Read Mapping Ratio >= 0.5 | AA6: 0.9262 | AB6: 0.99
A7: Brucella_melitensis__tier5_mid_high__27795reads | B7: Brucella suis | D7: bowtie2 | E7: TRUE | F7: 79 | G7: 4.9807864 | H7: 0.0039651544 | I7: TRUE | J7: 0 | K7: FALSE | L7: 24155 | M7: 305.7595 | N7: 0.4586X | O7: 36.44% | P7: 62.95 | Q7: 62 | R7: 0.160412 | S7: 0.9888 | T7: 0.9906 | U7: 99.28% | V7: 0.8662 | W7: 0.8603 | X7: #2 | Y7: 9/10 | Z7: E-value > 0.001, Reads >= 20, ANI > 96.5%, 5' C>T Damage >= 0.01, Breadth Ratio >= 0.8, Entropy (1000bp) >= 0.8 (bacteria), Edit distance damaged >= 0.5, Edit distance default (non-damaged) >= 0.6, Read Mapping Ratio >= 0.5 | AA7: 0.9226 | AB7: 0.9888
A8: Brucella_melitensis__tier6_high__120000reads | B8: Brucella melitensis | D8: bowtie2 | E8: TRUE | F8: 7430 | G8: 21.586717 | H8: 1.6479591 | I8: TRUE | J8: 0 | K8: FALSE | L8: 108179 | M8: 14.5598 | N8: 2.0627X | O8: 86.72% | P8: 62.83 | Q8: 62 | R8: 0.164046 | S8: 0.9967 | T8: 0.9935 | U8: 99.43% | V8: 0.8718 | W8: 0.876 | X8: #1 | Y8: 10/10 | Z8: E-value > 0.001, Reads >= 20, ANI > 96.5%, 5' C>T Damage >= 0.01, Breadth Ratio >= 0.8, Entropy (1000bp) >= 0.8 (bacteria), Edit distance damaged >= 0.5, Edit distance default (non-damaged) >= 0.6, Genus Ranking = 1, Read Mapping Ratio >= 0.5 | AA8: 0.9823 | AB8: 0.9967
A9: Brucella_melitensis__tier6_high__120000reads | B9: Brucella abortus | D9: bowtie2 | E9: TRUE | F9: 85 | G9: 6.6989195 | H9: 0.018334424 | I9: TRUE | J9: 0 | K9: FALSE | L9: 1 | M9: 0.0118 | N9: 0X | O9: 0% | P9: 35 | Q9: 35 | R9: 0 | S9: 0 | T9: 1 | U9: 97.14% | W9: 0.3 | X9: #10 | Y9: 4/9 | Z9: E-value > 0.001, Reads >= 20, ANI > 96.5%, Breadth Ratio >= 0.8 | AA9: 0 | AB9: 0
A10: Brucella_melitensis__tier6_high__120000reads | B10: Brucella ovis | D10: bowtie2 | E10: TRUE | F10: 91 | G10: 4.3076463 | H10: 0.011550462 | I10: TRUE | J10: 0 | K10: FALSE | L10: 100451 | M10: 1103.8571 | N10: 1.928X | O10: 83.18% | P10: 62.87 | Q10: 62 | R10: 0.153975 | S10: 0.996 | T10: 0.9734 | U10: 99.26% | V10: 0.8646 | W10: 0.8571 | X10: #9 | Y10: 9/10 | Z10: E-value > 0.001, Reads >= 20, ANI > 96.5%, 5' C>T Damage >= 0.01, Breadth Ratio >= 0.8, Entropy (1000bp) >= 0.8 (bacteria), Edit distance damaged >= 0.5, Edit distance default (non-damaged) >= 0.6, Read Mapping Ratio >= 0.5 | AA10: 0.9798 | AB10: 0.996
A11: Brucella_melitensis__tier6_high__120000reads | B11: Brucella suis | D11: bowtie2 | E11: TRUE | F11: 393 | G11: 4.0924675 | H11: 0.013014595 | I11: TRUE | J11: 0 | K11: FALSE | L11: 103420 | M11: 263.1552 | N11: 1.9617X | O11: 84.13% | P11: 62.88 | Q11: 62 | R11: 0.155998 | S11: 0.9957 | T11: 0.979 | U11: 99.29% | V11: 0.8655 | W11: 0.8597 | X11: #2 | Y11: 9/10 | Z11: E-value > 0.001, Reads >= 20, ANI > 96.5%, 5' C>T Damage >= 0.01, Breadth Ratio >= 0.8, Entropy (1000bp) >= 0.8 (bacteria), Edit distance damaged >= 0.5, Edit distance default (non-damaged) >= 0.6, Read Mapping Ratio >= 0.5 | AA11: 0.9803 | AB11: 0.9957
A12: Coxiella_burnetii__tier1_very_low__80reads | B12: Coxiella burnetii | D12: bowtie2 | E12: TRUE | F12: 76 | G12: 31.791791 | H12: 0.028292661 | I12: TRUE | J12: 0 | K12: FALSE | L12: 276 | M12: 3.6316 | N12: 0.0066X | O12: 0.33% | P12: 48.64 | Q12: 42 | R12: 0.068966 | S12: 0.4289 | T12: 0.5058 | U12: 98.80% | V12: 0.8875 | W12: 0.6996 | X12: #1 | Y12: 8/10 | Z12: E-value > 0.001, Reads >= 50, ANI > 96.5%, 5' C>T Damage >= 0.01, Edit distance damaged >= 0.5, Edit distance default (non-damaged) >= 0.6, Genus Ranking = 1, Read Mapping Ratio >= 0.5 | AA12: 0.404 | AB12: 0.4289
A13: Coxiella_burnetii__tier2_low__345reads | B13: Coxiella burnetii | D13: bowtie2 | E13: TRUE | F13: 331 | G13: 28.786717 | H13: 0.098600562 | I13: TRUE | J13: 0 | K13: FALSE | L13: 522 | M13: 1.577 | N13: 0.0141X | O13: 1.07% | P13: 55.01 | Q13: 52 | R13: 0.12037 | S13: 0.6427 | T13: 0.7652 | U13: 99.20% | V13: 0.8809 | W13: 0.8466 | X13: #1 | Y13: 8/10 | Z13: E-value > 0.001, Reads >= 50, ANI > 96.5%, 5' C>T Damage >= 0.01, Edit distance damaged >= 0.5, Edit distance default (non-damaged) >= 0.6, Genus Ranking = 1, Read Mapping Ratio >= 0.5 | AA13: 0.5436 | AB13: 0.6427
A14: Coxiella_burnetii__tier3_low_mid__1491reads | B14: Coxiella burnetii | D14: bowtie2 | E14: TRUE | F14: 1416 | G14: 30.910465 | H14: 0.43569199 | I14: TRUE | J14: 0 | K14: FALSE | L14: 1588 | M14: 1.1215 | N14: 0.0467X | O14: 4.26% | P14: 59.78 | Q14: 59 | R14: 0.172414 | S14: 0.8651 | T14: 0.9346 | U14: 99.41% | V14: 0.8756 | W14: 0.8688 | X14: #1 | Y14: 10/10 | Z14: E-value > 0.001, Reads >= 50, ANI > 96.5%, 5' C>T Damage >= 0.01, Breadth Ratio >= 0.8, Entropy (1000bp) >= 0.8 (bacteria), Edit distance damaged >= 0.5, Edit distance default (non-damaged) >= 0.6, Genus Ranking = 1, Read Mapping Ratio >= 0.5 | AA14: 0.711 | AB14: 0.8651
A15: Coxiella_burnetii__tier4_mid__6438reads | B15: Coxiella burnetii | D15: bowtie2 | E15: TRUE | F15: 6121 | G15: 39.337959 | H15: 1.8932896 | I15: TRUE | J15: 0 | K15: FALSE | L15: 6199 | M15: 1.0127 | N15: 0.1888X | O15: 16.99% | P15: 61.91 | Q15: 61 | R15: 0.157978 | S15: 0.9677 | T15: 0.9876 | U15: 99.53% | V15: 0.8774 | W15: 0.8777 | X15: #1 | Y15: 10/10 | Z15: E-value > 0.001, Reads >= 50, ANI > 96.5%, 5' C>T Damage >= 0.01, Breadth Ratio >= 0.8, Entropy (1000bp) >= 0.8 (bacteria), Edit distance damaged >= 0.5, Edit distance default (non-damaged) >= 0.6, Genus Ranking = 1, Read Mapping Ratio >= 0.5 | AA15: 0.853 | AB15: 0.9677
A16: Coxiella_burnetii__tier5_mid_high__27795reads | B16: Coxiella burnetii | D16: bowtie2 | E16: TRUE | F16: 26338 | G16: 71.187335 | H16: 5.5206603 | I16: TRUE | J16: 0 | K16: FALSE | L16: 25882 | M16: 0.9827 | N16: 0.7965X | O16: 54.38% | P16: 62.56 | Q16: 62 | R16: 0.169108 | S16: 0.9924 | T16: 0.9903 | U16: 99.54% | V16: 0.8781 | W16: 0.88 | X16: #1 | Y16: 10/10 | Z16: E-value > 0.001, Reads >= 50, ANI > 96.5%, 5' C>T Damage >= 0.01, Breadth Ratio >= 0.8, Entropy (1000bp) >= 0.8 (bacteria), Edit distance damaged >= 0.5, Edit distance default (non-damaged) >= 0.6, Genus Ranking = 1, Read Mapping Ratio >= 0.5 | AA16: 0.9518 | AB16: 0.9924
A17: Coxiella_burnetii__tier6_high__120000reads | B17: Coxiella burnetii | D17: bowtie2 | E17: TRUE | F17: 113918 | G17: 208.13935 | H17: 7.8701773 | I17: TRUE | J17: 0 | K17: FALSE | L17: 109725 | M17: 0.9632 | N17: 3.3847X | O17: 95.13% | P17: 62.71 | Q17: 62 | R17: 0.171034 | S17: 0.9973 | T17: 0.9847 | U17: 99.54% | V17: 0.8762 | W17: 0.8806 | X17: #1 | Y17: 10/10 | Z17: E-value > 0.001, Reads >= 50, ANI > 96.5%, 5' C>T Damage >= 0.01, Breadth Ratio >= 0.8, Entropy (1000bp) >= 0.8 (bacteria), Edit distance damaged >= 0.5, Edit distance default (non-damaged) >= 0.6, Genus Ranking = 1, Read Mapping Ratio >= 0.5 | AA17: 0.9886 | AB17: 0.9973
A18: Erysipelothrix_rhusiopathiae__tier1_very_low__80reads | B18: Erysipelothrix rhusiopathiae | D18: bowtie2 | E18: TRUE | F18: 69 | G18: 30.956148 | H18: 0.024425739 | I18: TRUE | J18: 0 | K18: FALSE | L18: 76 | M18: 1.1014 | N18: 0.0028X | O18: 0.28% | P18: 64.78 | Q18: 62 | R18: 0.181818 | S18: 0.579 | T18: 1.0014 | U18: 99.47% | V18: 0.6811 | W18: 0.8855 | X18: #1 | Y18: 9/10 | Z18: E-value > 0.001, Reads >= 50, ANI > 96.5%, 5' C>T Damage >= 0.01, Breadth Ratio >= 0.8, Edit distance damaged >= 0.5, Edit distance default (non-damaged) >= 0.6, Genus Ranking = 1, Read Mapping Ratio >= 0.5 | AA18: 0.4427 | AB18: 0.579
A19: Erysipelothrix_rhusiopathiae__tier2_low__345reads | B19: Erysipelothrix rhusiopathiae | D19: bowtie2 | E19: TRUE | F19: 300 | G19: 30.072536 | H19: 0.09787964 | I19: TRUE | J19: 0 | K19: FALSE | L19: 319 | M19: 1.0633 | N19: 0.0113X | O19: 1.12% | P19: 62.8 | Q19: 61 | R19: 0.183333 | S19: 0.7529 | T19: 0.9938 | U19: 99.68% | V19: 0.8919 | W19: 0.8862 | X19: #1 | Y19: 9/10 | Z19: E-value > 0.001, Reads >= 50, ANI > 96.5%, 5' C>T Damage >= 0.01, Breadth Ratio >= 0.8, Edit distance damaged >= 0.5, Edit distance default (non-damaged) >= 0.6, Genus Ranking = 1, Read Mapping Ratio >= 0.5 | AA19: 0.5872 | AB19: 0.7529
A20: Erysipelothrix_rhusiopathiae__tier3_low_mid__1491reads | B20: Erysipelothrix rhusiopathiae | D20: bowtie2 | E20: TRUE | F20: 1344 | G20: 29.115258 | H20: 0.3726125 | I20: TRUE | J20: 0 | K20: FALSE | L20: 1401 | M20: 1.0424 | N20: 0.0492X | O20: 4.8% | P20: 62.2 | Q20: 61 | R20: 0.162879 | S20: 0.9011 | T20: 0.9991 | U20: 99.63% | V20: 0.8827 | W20: 0.8851 | X20: #1 | Y20: 10/10 | Z20: E-value > 0.001, Reads >= 50, ANI > 96.5%, 5' C>T Damage >= 0.01, Breadth Ratio >= 0.8, Entropy (1000bp) >= 0.8 (bacteria), Edit distance damaged >= 0.5, Edit distance default (non-damaged) >= 0.6, Genus Ranking = 1, Read Mapping Ratio >= 0.5 | AA20: 0.7345 | AB20: 0.9011
A21: Erysipelothrix_rhusiopathiae__tier4_mid__6438reads | B21: Erysipelothrix rhusiopathiae | D21: bowtie2 | E21: TRUE | F21: 5743 | G21: 35.935522 | H21: 1.5912129 | I21: TRUE | J21: 0 | K21: FALSE | L21: 5968 | M21: 1.0392 | N21: 0.2112X | O21: 19.05% | P21: 62.66 | Q21: 62 | R21: 0.178538 | S21: 0.9749 | T21: 1.0004 | U21: 99.59% | V21: 0.8777 | W21: 0.8826 | X21: #1 | Y21: 10/10 | Z21: E-value > 0.001, Reads >= 50, ANI > 96.5%, 5' C>T Damage >= 0.01, Breadth Ratio >= 0.8, Entropy (1000bp) >= 0.8 (bacteria), Edit distance damaged >= 0.5, Edit distance default (non-damaged) >= 0.6, Genus Ranking = 1, Read Mapping Ratio >= 0.5 | AA21: 0.8652 | AB21: 0.9749
... A30: Leptospira_borgpetersenii__tier6_high__120000reads | B30: Leptospira weilii | D30: bowtie2 | E30: TRUE | F30: 188 | G30: 7.4350962 | H30: 0.0031483963 | I30: TRUE | J30: 0 | K30: FALSE | L30: 8326 | M30: 44.2872 | N30: 0.1065X | O30: 7.71% | P30: 56.05 | Q30: 53 | R30: 0.088418 | S30: 0.9064 | T30: 0.7626 | U30: 98.22% | V30: 0.8494 | W30: 0.182 | X30: #3 | Y30: 7/10 | Z30: E-value > 0.001, Reads >= 50, ANI > 96.5%, 5' C>T Damage >= 0.01, Entropy (1000bp) >= 0.8 (bacteria), Edit distance damaged >= 0.5, Read Mapping Ratio >= 0.5 | AA30: 0.7952 | AB30: 0.9064
A31: Mycobacterium_leprae__tier3_low_mid__1491reads | B31: Mycobacterium avium | D31: bowtie2 | E31: TRUE | F31: 94 | G31: 9.1858385 | H31: 0.0010557979 | I31: TRUE | J31: 0 | K31: FALSE | L31: 504 | M31: 5.3617 | N31: 0.0042X | O31: 0.23% | P31: 42.89 | Q31: 38 | R31: 0.011834 | S31: 0.5113 | T31: 0.5517 | U31: 98.24% | V31: 0.875 | W31: 0.1957 | Y31: 6/10 | Z31: E-value > 0.001, Reads >= 50, ANI > 96.5%, 5' C>T Damage >= 0.01, Edit distance damaged >= 0.5, Read Mapping Ratio >= 0.5 | AA31: 0.4676 | AB31: 0.5113
A32: Mycobacterium_leprae__tier4_mid__6438reads | B32: Mycobacterium avium | D32: bowtie2 | E32: TRUE | F32: 165 | G32: 15.345601 | H32: 0.0051601842 | I32: TRUE | J32: 0 | K32: FALSE | L32: 571 | M32: 3.4606 | N32: 0.005X | O32: 0.31% | P32: 44.94 | Q32: 39 | R32: 0.011173 | S32: 0.5421 | T32: 0.6168 | U32: 98.41% | V32: 0.875 | W32: 0.2165 | Y32: 6/10 | Z32: E-value > 0.001, Reads >= 50, ANI > 96.5%, 5' C>T Damage >= 0.01, Edit distance damaged >= 0.5, Read Mapping Ratio >= 0.5 | AA32: 0.4902 | AB32: 0.5421
A33: Mycobacterium_leprae__tier5_mid_high__27795reads | B33: Mycobacterium avium | D33: bowtie2 | E33: TRUE | F33: 464 | G33: 22.903838 | H33: 0.032012282 | I33: TRUE | J33: 0 | K33: FALSE | L33: 884 | M33: 1.9052 | N33: 0.0087X | O33: 0.62% | P33: 50.9 | Q33: 45 | R33: 0.040441 | S33: 0.5992 | T33: 0.7215 | U33: 98.74% | V33: 0.8712 | W33: 0.282 | Y33: 6/10 | Z33: E-value > 0.001, Reads >= 50, ANI > 96.5%, 5' C>T Damage >= 0.01, Edit distance damaged >= 0.5, Read Mapping Ratio >= 0.5 | AA33: 0.5525 | AB33: 0.5992
A34: Mycobacterium_leprae__tier6_high__120000reads | B34: Mycobacterium avium | D34: bowtie2 | E34: TRUE | F34: 1838 | G34: 20.550594 | H34: 0.098727903 | I34: TRUE | J34: 0 | K34: FALSE | L34: 2212 | M34: 1.2035 | N34: 0.024X | O34: 1.52% | P34: 56.2 | Q34: 54 | R34: 0.114659 | S34: 0.6308 | T34: 0.6411 | U34: 98.97% | V34: 0.8706 | W34: 0.7714 | Y34: 7/10 | Z34: E-value > 0.001, Reads >= 50, ANI > 96.5%, 5' C>T Damage >= 0.01, Edit distance damaged >= 0.5, Edit distance default (non-damaged) >= 0.6, Read Mapping Ratio >= 0.5 | AA34: 0.6301 | AB34: 0.6308
A35: Sheeppox_virus__tier1_very_low__80reads | B35: Sheeppox virus | D35: bowtie2 | E35: TRUE | F35: 41 | G35: 20.333533 | H35: 0.23418049 | I35: TRUE | J35: 0 | K35: FALSE | L35: 79 | M35: 1.9268 | N35: 0.0339X | O35: 3.37% | P35: 64.27 | Q35: 62 | R35: 0.066667 | S35: 0.8204 | T35: 1.0108 | U35: 99.68% | V35: 0 | W35: 0.887 | X35: #1 | Y35: 9/10 | Z35: E-value > 0.001, Reads >= 1, ANI > 96.5%, 5' C>T Damage >= 0.01, Breadth Ratio >= 0.8, Entropy (1000bp) >= 0.7 (virus), Edit distance default (non-damaged) >= 0.6, Genus Ranking = 1, Read Mapping Ratio >= 0.5 | AA35: 0.5927 | AB35: 0.8204
A36: Sheeppox_virus__tier1_very_low__80reads | B36: Goatpox virus | D36: bowtie2 | E36: TRUE | F36: 1 | G36: 21.023646 | H36: 0.0050043 | I36: TRUE | J36: 0 | K36: FALSE | L36: 44 | M36: 44 | N36: 0.0186X | O36: 1.84% | P36: 63.32 | Q36: 62 | R36: 0 | S36: 0.7088 | T36: 0.9981 | U36: 98.67% | V36: 0 | W36: 0.1831 | X36: #2 | Y36: 6/10 | Z36: E-value > 0.001, Reads >= 1, ANI > 96.5%, Breadth Ratio >= 0.8, Entropy (1000bp) >= 0.7 (virus), Read Mapping Ratio >= 0.5 | AA36: 0.5176 | AB36: 0.7088
A37: Sheeppox_virus__tier2_low__345reads | B37: Sheeppox virus | D37: bowtie2 | E37: TRUE | F37: 171 | G37: 22.631896 | H37: 0.86417947 | I37: TRUE | J37: 0 | K37: FALSE | L37: 332 | M37: 1.9415 | N37: 0.1383X | O37: 12.84% | P37: 62.45 | Q37: 61 | R37: 0.157895 | S37: 0.9382 | T37: 0.9944 | U37: 99.73% | V37: 0.895 | W37: 0.8876 | X37: #1 | Y37: 10/10 | Z37: E-value > 0.001, Reads >= 1, ANI > 96.5%, 5' C>T Damage >= 0.01, Breadth Ratio >= 0.8, Entropy (1000bp) >= 0.7 (virus), Edit distance damaged >= 0.5, Edit distance default (non-damaged) >= 0.6, Genus Ranking = 1, Read Mapping Ratio >= 0.5 | AA37: 0.7714 | AB37: 0.9382
A38: Sheeppox_virus__tier2_low__345reads | B38: Goatpox virus | D38: bowtie2 | E38: TRUE | F38: 2 | G38: 8.5077469 | H38: 0.00163965 | I38: TRUE | J38: 0 | K38: FALSE | L38: 200 | M38: 100 | N38: 0.0822X | O38: 7.73% | P38: 61.5 | Q38: 60.5 | R38: 0.227273 | S38: 0.8984 | T38: 0.9797 | U38: 98.72% | V38: 0.87 | W38: 0.2089 | X38: #3 | Y38: 8/10 | Z38: E-value > 0.001, Reads >= 1, ANI > 96.5%, 5' C>T Damage >= 0.01, Breadth Ratio >= 0.8, Entropy (1000bp) >= 0.7 (virus), Edit distance damaged >= 0.5, Read Mapping Ratio >= 0.5 | AA38: 0.7086 | AB38: 0.8984
A39: Sheeppox_virus__tier2_low__345reads | B39: Lumpy skin disease virus | D39: bowtie2 | E39: TRUE | F39: 3 | G39: 11.360024 | H39: 0.0056451333 | I39: TRUE | J39: 0 | K39: FALSE | L39: 220 | M39: 73.3333 | N39: 0.0913X | O39: 8.61% | P39: 62.56 | Q39: 61 | R39: 0.206897 | S39: 0.9126 | T39: 0.9873 | U39: 98.74% | V39: 0.832 | W39: 0.2637 | X39: #2 | Y39: 8/10 | Z39: E-value > 0.001, Reads >= 1, ANI > 96.5%, 5' C>T Damage >= 0.01, Breadth Ratio >= 0.8, Entropy (1000bp) >= 0.7 (virus), Edit distance damaged >= 0.5, Read Mapping Ratio >= 0.5 | AA39: 0.7198 | AB39: 0.9126
A40: Sheeppox_virus__tier3_low_mid__1491reads | B40: Sheeppox virus | D40: bowtie2 | E40: TRUE | F40: 734 | G40: 37.152883 | H40: 2.8591188 | I40: TRUE | J40: 0 | K40: FALSE | L40: 1417 | M40: 1.9305 | N40: 0.5853X | O40: 44.06% | P40: 61.94 | Q40: 61 | R40: 0.14881 | S40: 0.9824 | T40: 0.9944 | U40: 99.68% | V40: 0.8828 | W40: 0.8866 | X40: #1 | Y40: 10/10 | Z40: E-value > 0.001, Reads >= 1, ANI > 96.5%, 5' C>T Damage >= 0.01, Breadth Ratio >= 0.8, Entropy (1000bp) >= 0.7 (virus), Edit distance damaged >= 0.5, Edit distance default (non-damaged) >= 0.6, Genus Ranking = 1, Read Mapping Ratio >= 0.5 | AA40: 0.9157 | AB40: 0.9824
A41: Sheeppox_virus__tier3_low_mid__1491reads | B41: Goatpox virus | D41: bowtie2 | E41: TRUE | F41: 34 | G41: 6.4570237 | H41: 0.015719735 | I41: TRUE | J41: 0 | K41: FALSE | L41: 805 | M41: 23.6765 | N41: 0.3326X | O41: 26.41% | P41: 61.81 | Q41: 62 | R41: 0.078652 | S41: 0.9645 | T41: 0.9336 | U41: 98.64% | V41: 0.6501 | W41: 0.2408 | X41: #2 | Y41: 8/10 | Z41: E-value > 0.001, Reads >= 1, ANI > 96.5%, 5' C>T Damage >= 0.01, Breadth Ratio >= 0.8, Entropy (1000bp) >= 0.7 (virus), Edit distance damaged >= 0.5, Read Mapping Ratio >= 0.5 | AA41: 0.8566 | AB41: 0.9645
A42: Sheeppox_virus__tier3_low_mid__1491reads | B42: Lumpy skin disease virus | D42: bowtie2 | E42: TRUE | F42: 24 | G42: 7.8076196 | H42: 0.020889583 | I42: TRUE | J42: 0 | K42: FALSE | L42: 890 | M42: 37.0833 | N42: 0.3669X | O42: 29.62% | P42: 62.17 | Q42: 61 | R42: 0.085714 | S42: 0.9653 | T42: 0.9644 | U42: 98.75% | V42: 0.8245 | W42: 0.6907 | X42: #3 | Y42: 9/10 | Z42: E-value > 0.001, Reads >= 1, ANI > 96.5%, 5' C>T Damage >= 0.01, Breadth Ratio >= 0.8, Entropy (1000bp) >= 0.7 (virus), Edit distance damaged >= 0.5, Edit distance default (non-damaged) >= 0.6, Read Mapping Ratio >= 0.5 | AA42: 0.8693 | AB42: 0.9653
A43: Sheeppox_virus__tier4_mid__6438reads | B43: Sheeppox virus | D43: bowtie2 | E43: TRUE | F43: 3160 | G43: 110.12052 | H43: 5.1554672 | I43: TRUE | J43: 0 | K43: FALSE | L43: 6056 | M43: 1.9165 | N43: 2.5244X | O43: 89.57% | P43: 62.51 | Q43: 61 | R43: 0.175623 | S43: 0.9919 | T43: 0.9736 | U43: 99.70% | V43: 0.8838 | W43: 0.8872 | X43: #1 | Y43: 10/10 | Z43: E-value > 0.001, Reads >= 1, ANI > 96.5%, 5' C>T Damage >= 0.01, Breadth Ratio >= 0.8, Entropy (1000bp) >= 0.7 (virus), Edit distance damaged >= 0.5, Edit distance default (non-damaged) >= 0.6, Genus Ranking = 1, Read Mapping Ratio >= 0.5 | AA43: 0.9783 | AB43: 0.9919
A44: Sheeppox_virus__tier4_mid__6438reads | B44: Goatpox virus | D44: bowtie2 | E44: TRUE | F44: 76 | G44: 5.9000255 | H44: 0.028642895 | I44: TRUE | J44: 0 | K44: FALSE | L44: 3471 | M44: 45.6711 | N44: 1.4398X | O44: 63.77% | P44: 62.06 | Q44: 61 | R44: 0.1225 | S44: 0.9815 | T44: 0.8358 | U44: 98.65% | V44: 0.8487 | W44: 0.2459 | X44: #3 | Y44: 8/10 | Z44: E-value > 0.001, Reads >= 1, ANI > 96.5%, 5' C>T Damage >= 0.01, Breadth Ratio >= 0.8, Entropy (1000bp) >= 0.7 (virus), Edit distance damaged >= 0.5, Read Mapping Ratio >= 0.5 | AA44: 0.9428 | AB44: 0.9815
A45: Sheeppox_virus__tier4_mid__6438reads | B45: Lumpy skin disease virus | D45: bowtie2 | E45: TRUE | F45: 98 | G45: 4.8891394 | H45: 0.032181714 | I45: TRUE | J45: 0 | K45: FALSE | L45: 3909 | M45: 39.8878 | N45: 1.6095X | O45: 68.43% | P45: 62.08 | Q45: 61 | R45: 0.139785 | S45: 0.9823 | T45: 0.8554 | U45: 98.78% | V45: 0.8473 | W45: 0.6306 | X45: #2 | Y45: 9/10 | Z45: E-value > 0.001, Reads >= 1, ANI > 96.5%, 5' C>T Damage >= 0.01, Breadth Ratio >= 0.8, Entropy (1000bp) >= 0.7 (virus), Edit distance damaged >= 0.5, Edit distance default (non-damaged) >= 0.6, Read Mapping Ratio >= 0.5 | AA45: 0.9482 | AB45: 0.9823
A46: Sheeppox_virus__tier5_mid_high__27795reads | B46: Sheeppox virus | D46: bowtie2 | E46: TRUE | F46: 13645 | G46: 77.112898 | H46: 2.1507108 | I46: TRUE | J46: 0 | K46: FALSE | L46: 25180 | M46: 1.8454 | N46: 10.5586X | O46: 97.12% | P46: 62.88 | Q46: 62 | R46: 0.18654 | S46: 0.9941 | T46: 0.9712 | U46: 99.69% | V46: 0.8837 | W46: 0.8877 | X46: #1 | Y46: 10/10 | Z46: E-value > 0.001, Reads >= 1, ANI > 96.5%, 5' C>T Damage >= 0.01, Breadth Ratio >= 0.8, Entropy (1000bp) >= 0.7 (virus), Edit distance damaged >= 0.5, Edit distance default (non-damaged) >= 0.6, Genus Ranking = 1, Read Mapping Ratio >= 0.5 | AA46: 0.9923 | AB46: 0.9941
... A83: Yersinia_pestis__tier6_high__120000reads | B83: Yersinia pestis | D83: bowtie2 | E83: TRUE | F83: 11705 | G83: 31.441076 | H83: 2.4461261 | I83: TRUE | J83: 0 | K83: FALSE | L83: 105950 | M83: 9.0517 | N83: 1.4262X | O83: 73.99% | P83: 62.71 | Q83: 62 | R83: 0.171088 | S83: 0.9935 | T83: 0.9738 | U83: 99.50% | V83: 0.8756 | W83: 0.8788 | X83: #1 | Y83: 10/10 | Z83: E-value > 0.001, Reads >= 20, ANI > 96.5%, 5' C>T Damage >= 0.01, Breadth Ratio >= 0.8, Entropy (1000bp) >= 0.8 (bacteria), Edit distance damaged >= 0.5, Edit distance default (non-damaged) >= 0.6, Genus Ranking = 1, Read Mapping Ratio >= 0.5 | AA83: 0.9737 | AB83: 0.9935

Sheet S4  Samples infos
A1: samp_name | B1: biosamples_accession | C1: Tissue | D1: tissue_detailled | E1: samp_taxon_common | F1: Basic_taxon_name | G1: specific_host | H1: latitude | I1: longitude | J1: geo_loc_name | K1: site_name | L1: sample_age | M1: sample_age_upper | N1: sample_age_lower
A2: 10304 | B2: SAMEA3909844; SAMEA3909853 | C2: soft_tissue | D2: skin of body, UBERON:0002097 | E2: Sheep | F2: Ovis | G2: Ovis, Ovis aries | H2: 46.779423845180986 | I2: 10.839684636412922 | J2: Italy | K2: Otzal Alps | L2: 5177.5 | M2: 5300 | N2: 5055
A3: OCD | B3: SAMEA3909841; SAMEA3909850 | C3: soft_tissue | D3: skin of body, UBERON:0002097 | E3: Sheep | F3: Ovis | G3: Ovis, Ovis aries | H3: 46.779423845180986 | I3: 10.839684636412922 | J3: Italy | K3: Otzal Alps | L3: 5177.5 | M3: 5300 | N3: 5055
A4: OCL2 | B4: SAMEA3909842; SAMEA3909851 | C4: soft_tissue | D4: skin of body, UBERON:0002097 | E4: Sheep | F4: Ovis | G4: Ovis, Ovis aries | H4: 46.779423845180986 | I4: 10.839684636412922 | J4: Italy | K4: Otzal Alps | L4: 5177.5 | M4: 5300 | N4: 5055
A5: OLC | B5: SAMEA3909852; SAMEA3909843 | C5: soft_tissue | D5: skin of body, UBERON:0002097 | E5: Sheep | F5: Ovis | G5: Ovis, Ovis aries | H5: 46.779423845180986 | I5: 10.839684636412922 | J5: Italy | K5: Otzal Alps | L5: 5177.5 | M5: 5300 | N5: 5055
A6: Alzey1 | B6: SAMEA113400629 | C6: petrous_cranial | D6: petrous part of temporal bone, UBERON:0001694 | E6: Sheep | F6: Ovis | G6: Ovis, Ovis aries | H6: 49.746201 | I6: 8.1171135 | J6: Germany | K6: Alzey | L6: 1700 | M6: 1900 | N6: 1500
A7: Asikli1 | B7: SAMEA113400630 | C7: long_bone | D7: humerus, UBERON:0000976 | E7: Sheep | F7: Ovis | G7: Ovis, Ovis aries | H7: 38.34935 | I7: 34.230237 | J7: Turkey | K7: Aşıklı Höyük | L7: 9608 | M7: 9679 | N7: 9536
A8: Asikli2 | B8: SAMEA113400631 | C8: long_bone | D8: humerus, UBERON:0000976 | E8: Sheep | F8: Ovis | G8: Ovis, Ovis aries | H8: 38.34935 | I8: 34.230237 | J8: Turkey | K8: Aşıklı Höyük | L8: 9750 | M8: 9950 | N8: 9550
A9: Asikli3 | B9: SAMEA113400632 | C9: long_bone | D9: humerus, UBERON:0000976 | E9: Sheep | F9: Ovis | G9: Ovis, Ovis aries | H9: 38.34935 | I9: 34.230237 | J9: Turkey | K9: Aşıklı Höyük | L9: 10200 | M9: 10400 | N9: 10000
A10: Asikli4 | B10: SAMEA113400633 | C10: long_bone | D10: humerus, UBERON:0000976 | E10: Sheep | F10: Ovis | G10: Ovis, Ovis aries | H10: 38.34935 | I10: 34.230237 | J10: Turkey | K10: Aşıklı Höyük | L10: 10200 | M10: 10400 | N10: 10000
A11: Asikli5 | B11: SAMEA113400634 | C11: long_bone | D11: humerus, UBERON:0000976 | E11: Sheep | F11: Ovis | G11: Ovis, Ovis aries | H11: 38.34935 | I11: 34.230237 | J11: Turkey | K11: Aşıklı Höyük | L11: 9904 | M11: 10118 | N11: 9689
A12: Asikli6 | B12: SAMEA113400635 | C12: long_bone | D12: femur, UBERON:0000981 | E12: Sheep | F12: Ovis | G12: Ovis, Ovis aries | H12: 38.34935 | I12: 34.230237 | J12: Turkey | K12: Aşıklı Höyük | L12: 9724 | M12: 9891 | N12: 9557
A13: Asikli8 | B13: SAMEA113400637 | C13: petrous_cranial | D13: petrous part of temporal bone, UBERON:0001694 | E13: Sheep | F13: Ovis | G13: Ovis, Ovis aries | H13: 38.34935 | I13: 34.230237 | J13: Turkey | K13: Aşıklı Höyük | L13: 9860 | M13: 10111 | N13: 9608
A14: Blagotin10 | B14: SAMEA113400641 | C14: petrous_cranial | D14: petrous part of temporal bone, UBERON:0001694 | E14: Sheep | F14: Ovis | G14: Ovis, Ovis aries | H14: 43.717483 | I14: 21.097898 | J14: Serbia | K14: Blagotin-Poljna | L14: 8225 | M14: 8425 | N14: 8025
A15: Blagotin11 | B15: SAMEA113400642 | C15: petrous_cranial | D15: petrous part of temporal bone, UBERON:0001694 | E15: Sheep | F15: Ovis | G15: Ovis, Ovis aries | H15: 43.717483 | I15: 21.097898 | J15: Serbia | K15: Blagotin-Poljna | L15: 8225 | M15: 8425 | N15: 8025
A16: Blagotin13 | B16: SAMEA113400643 | C16: petrous_cranial | D16: petrous part of temporal bone, UBERON:0001694 | E16: Sheep | F16: Ovis | G16: Ovis, Ovis aries | H16: 43.717483 | I16: 21.097898 | J16: Serbia | K16: Blagotin-Poljna | L16: 8225 | M16: 8425 | N16: 8025
A17: Blagotin15 | B17: SAMEA115573856 | C17: petrous_cranial | D17: petrous part of temporal bone, UBERON:0001694 | E17: Sheep | F17: Ovis | G17: Ovis, Ovis aries | H17: 43.717483 | I17: 21.097898 | J17: Serbia | K17: Blagotin-Poljna | L17: 8225 | M17: 8425 | N17: 8025
... A85: Azer13 | B85: SAMEA113400639 | C85: petrous_cranial | D85: petrous part of temporal bone, UBERON:0001694 | E85: Sheep | F85: Ovis | G85: Ovis, Ovis aries | H85: 36.54426 | I85: 46.211329 | J85: Iran | K85: Ali Abad | L85: 4500 | M85: 4700 | N85: 4300
A86: Azer2 | B86: SAMEA8609222 | C86: petrous_cranial | D86: petrous part of temporal bone, UBERON:0001694 | E86: Sheep | F86: Ovis | G86: Ovis, Ovis aries | H86: 37.004527 | I86: 45.458845 | J86: Iran | K86: Tepe Hasanlu | L86: 2550 | M86: 2750 | N86: 2650
A87: bad003 | B87: SAMEA114638840; SAMEA114806684 | C87: missing | D87: missing | E87: Sheep | F87: Ovis | G87: Ovis, Ovis aries | H87: 37.213233 | I87: 30.475069 | J87: Turkey | K87: Bademağacı | L87: 8820 | M87: 8985 | N87: 8655
A88: bar001 | B88: SAMEA114638841; SAMEA114806685 | C88: missing | D88: missing | E88: Sheep | F88: Ovis | G88: Ovis, Ovis aries | H88: 40.301024 | I88: 29.608647 | J88: Turkey | K88: Barcın | L88: 8200 | M88: 8250 | N88: 8150
A89: BFMC304A | B89: SAMEA116133605 | C89: petrous_cranial | D89: petrous part of temporal bone, UBERON:0001694 | E89: Sheep | F89: Ovis | G89: Ovis, Ovis aries | H89: 49.388729 | I89: 3.3938687 | J89: France | K89: Bucy-le-Long "le Fond du Marais", Picardie | L89: 6750 | M89: 6850 | N89: 6650
A90: BFMC304B | B90: SAMEA116133606 | C90: petrous_cranial | D90: petrous part of temporal bone, UBERON:0001694 | E90: Sheep | F90: Ovis | G90: Ovis, Ovis aries | H90: 49.388729 | I90: 3.3938687 | J90: France | K90: Bucy-le-Long "le Fond du Marais", Picardie | L90: 6750 | M90: 6850 | N90: 6650
A91: Chalow2 | B91: SAMEA113400640 | C91: petrous_cranial | D91: petrous part of temporal bone, UBERON:0001694 | E91: Sheep | F91: Ovis | G91: Ovis, Ovis aries | H91: 37.10355 | I91: 56.885281 | J91: Iran | K91: Chalow | L91: 4400 | M91: 4600 | N91: 4200
A92: Chishma1 | B92: SAMEA113400652 | C92: other_bone | D92: talus, UBERON:0002395 | E92: Sheep | F92: Ovis | G92: Ovis, Ovis aries | H92: 54.249722 | I92: 55.546944 | J92: Russia | K92: Chishminskoye | L92: 3481 | M92: 3564 | N92: 3398
A93: Enkhuizen1 | B93: SAMEA113400658 | C93: petrous_cranial | D93: petrous part of temporal bone, UBERON:0001694 | E93: Sheep | F93: Ovis | G93: Ovis, Ovis aries | H93: 52.7 | I93: 5.3 | J93: Netherlands | K93: Enkhuizen | L93: 3080 | M93: 3162 | N93: 2998
A94: erb002 | B94: SAMEA114638842; SAMEA114806686 | C94: missing | D94: missing | E94: Sheep | F94: Ovis | G94: Ovis, Ovis aries | H94: 37.352004 | I94: 31.925888 | J94: Turkey | K94: Erbaba Höyük | L94: 8100 | M94: 8250 | N94: 7950
A95: ERB455 | B95: SAMEA114638850 | C95: other_bone | D95: scapula, UBERON:0006849 | E95: Sheep | F95: Ovis | G95: Ovis, Ovis aries | H95: 37.352004 | I95: 31.925888 | J95: Turkey | K95: Erbaba Höyük | L95: 8200 | M95: 8450 | N95: 7950
A96: Fars3 | B96: SAMEA113400659 | C96: petrous_cranial | D96: petrous part of temporal bone, UBERON:0001694 | E96: Sheep | F96: Ovis | G96: Ovis, Ovis aries | H96: 29.175287 | I96: 52.765664 | J96: Iran | K96: Tepe Qasrdasht | L96: 5867 | M96: 5985 | N96: 5749
A97: Gadachrili3 | B97: SAMEA113400661 | C97: petrous_cranial | D97: petrous part of temporal bone, UBERON:0001694 | E97: Sheep | F97: Ovis | G97: Ovis, Ovis aries | H97: 41.39055 | I97: 44.82084 | J97: Georgia | K97: Gadachrili Gora | L97: 7850 | M97: 8050 | N97: 7650
A98: Gadachrili4 | B98: SAMEA113400662 | C98: petrous_cranial | D98: petrous part of temporal bone, UBERON:0001694 | E98: Sheep | F98: Ovis | G98: Ovis, Ovis aries | H98: 41.39055 | I98: 44.82084 | J98: Georgia | K98: Gadachrili Gora | L98: 7863 | M98: 7970 | N98: 7755
... A108: Jelsum2 | B108: SAMEA113400689 | C108: petrous_cranial | D108: petrous part of temporal bone, UBERON:0001694 | E108: Sheep | F108: Ovis | G108: Ovis, Ovis aries | H108: 53.23 | I108: 5.78 | J108: Netherlands | K108: Jelsum | L108: 2081 | M108: 2281 | N108: 1881
A109: Khor1 | B109: SAMEA8609212 | C109: petrous_cranial | D109: petrous part of temporal bone, UBERON:0001694 | E109: Sheep | F109: Ovis | G109: Ovis, Ovis aries | H109: 36.169834 | I109: 58.81134 | J109: Iran | K109: Nishapur | L109: 3000 | M109: 3300 | N109: 2700
A110: Kortik4 | B110: SAMEA113400695 | C110: petrous_cranial | D110: petrous part of temporal bone, UBERON:0001694 | E110: Mouflon | F110: Ovis | G110: Ovis, Ovis gmelini | H110: 37.81442 | I110: 40.98383 | J110: Turkey | K110: Körtiktepe | L110: 11613 | M110: 11823 | N110: 11403
A111: Kultepe1 | B111: SAMEA113400696 | C111: petrous_cranial | D111: petrous part of temporal bone, UBERON:0001694 | E111: Sheep | F111: Ovis | G111: Ovis, Ovis aries | H111: 39.270278 | I111: 45.451944 | J111: Azerbaijan | K111: Kültepe I | L111: 7723 | M111: 7923 | N111: 7523
A112: Kur1 | B112: SAMEA113400697 | C112: petrous_cranial | D112: petrous part of temporal bone, UBERON:0001694 | E112: Sheep | F112: Ovis | G112: Ovis, Ovis aries | H112: 35.776299 | I112: 48.12043 | J112: Iran | K112: Sad-e Talvar | L112: 6000 | M112: 6200 | N112: 5800
A113: Lur10 | B113: SAMEA113400698 | C113: petrous_cranial | D113: petrous part of temporal bone, UBERON:0001694 | E113: Sheep | F113: Ovis | G113: Ovis, Ovis aries | H113: 33.449951 | I113: 49.451685 | J113: Iran | K113: Tepe Qela Gap | L113: 7142 | M113: 7274 | N113: 7010
A114: Lur11 | B114: SAMEA113400699 | C114: petrous_cranial | D114: petrous part of temporal bone, UBERON:0001694 | E114: Sheep | F114: Ovis | G114: Ovis, Ovis aries | H114: 33.449951 | I114: 49.451685 | J114: Iran | K114: Tepe Qela Gap | L114: 5000 | M114: 5200 | N114: 4800
A115: Lur16 | B115: SAMEA113400700 | C115: petrous_cranial | D115: petrous part of temporal bone, UBERON:0001694 | E115: Sheep | F115: Ovis | G115: Ovis, Ovis aries | H115: 33.449951 | I115: 49.451685 | J115: Iran | K115: Tepe Qela Gap | L115: 5000 | M115: 5200 | N115: 4800
A116: MDVC564 | B116: SAMEA116133604 | C116: petrous_cranial | D116: petrous part of temporal bone, UBERON:0001694 | E116: Sheep | F116: Ovis | G116: Ovis, Ovis aries | H116: 49.431467 | I116: 4.0048772 | J116: France | K116: Mennevile-Derrière-Le-Village, Picardie | L116: 6950 | M116: 7050 | N116: 6850
...

Sheet S5  Pathogens Hits empirical da
A1: Sample | B1: Pathogen | C1: Host_best_species | D1: Host_aligner | E1: Pathogen_screening_only | F1: Krakenuniq_reads | G1: Escore | H1: Guellil_et_al_Evalue | I1: Detected_by_Krakenuniq | J1: HOPS_score | K1: Detected_by_HOPS | L1: Mapped_reads | M1: Read_mapping_ratio | N1: Coverage | O1: Evenness | P1: Read_length_mean | Q1: Read_length_median | R1: Damage_5p_CtoT | S1: Relative_entropy | T1: Breadth_ratio | U1: ANI | V1: Edit_distance_logR2 | W1: Genus_ranking | X1: Score | Y1: Criteria_passed | Z1: Relative_entropy_100bp | AA1: Relative_entropy_1000bp | AB1: Edit_distance_decay_quality | AC1: Edit_distance_decay_quality_no_damage
A2: LL157 | B2: Mannheimia haemolytica | D2: bowtie2 | E2: TRUE | F2: 201 | G2: 7.1023903 | H2: 0.0048176692 | I2: TRUE | J2: 0 | K2: FALSE | L2: 458 | M2: 2.2786 | N2: 0.0072X | O2: 0.57% | P2: 43.25 | Q2: 39 | R2: 0.014706 | S2: 0.6181 | T2: 0.7909 | U2: 98.57% | V2: 0 | W2: #1 | X2: 6/10 | Y2: E-value > 0.001, Reads >= 50, ANI > 96.5%, 5' C>T Damage >= 0.01, Genus Ranking = 1, Read Mapping Ratio >= 0.5 | Z2: 0.5522 | AA2: 0.6181 | AB2: 0 | AC2: 0.2667 | AD2: =VLOOKUP(A2,AE:AE,1,FALSE) -> #REF!
A3: LL157 | B3: Bibersteinia trehalosi | D3: bowtie2 | E3: TRUE | F3: 358 | G3: 10.244514 | H3: 0.012112522 | I3: TRUE | J3: 0 | K3: FALSE | L3: 415 | M3: 1.1592 | N3: 0.008X | O3: 0.62% | P3: 45.31 | Q3: 40 | R3: 0 | S3: 0.5819 | T3: 0.7708 | U3: 98.79% | V3: 0 | W3: #1 | X3: 6/10 | Y3: E-value > 0.001, Reads >= 50, ANI > 96.5%, Edit Distance No-Damage Decay Quality >= 0.6, Genus Ranking = 1, Read Mapping Ratio >= 0.5 | Z3: 0.5423 | AA3: 0.5819 | AB3: 0 | AC3: 0.7107 | AD3: =VLOOKUP(A3,AE:AE,1,FALSE) -> #REF!
A4: LL157 | B4: Streptococcus pyogenes | D4: bowtie2 | E4: TRUE | F4: 95 | G4: 9.2695295 | H4: 0.0013487158 | I4: TRUE | J4: 0 | K4: FALSE | L4: 118 | M4: 1.2421 | N4: 0.0028X | O4: 0.24% | P4: 41.29 | Q4: 37 | R4: 0 | S4: 0.5246 | T4: 0.8649 | U4: 98.65% | V4: 0 | W4: #6 | X4: 6/10 | Y4: E-value > 0.001, Reads >= 50, ANI > 96.5%, Breadth Ratio >= 0.8, Edit Distance No-Damage Decay Quality >= 0.6, Read Mapping Ratio >= 0.5 | Z4: 0.463 | AA4: 0.5246 | AB4: 0 | AC4: 0.6319 | AD4: =VLOOKUP(A4,AE:AE,1,FALSE) -> #REF!
A5: LL157 | B5: Streptococcus gallolyticus | D5: bowtie2 | E5: TRUE | F5: 176 | G5: 11.497622 | H5: 0.011500398 | I5: TRUE | J5: 0 | K5: FALSE | L5: 169 | M5: 0.9602 | N5: 0.0032X | O5: 0.27% | P5: 42.96 | Q5: 39 | R5: 0 | S5: 0.5031 | T5: 0.8432 | U5: 98.76% | V5: 0 | W5: #2 | X5: 6/10 | Y5: E-value > 0.001, Reads >= 50, ANI > 96.5%, Breadth Ratio >= 0.8, Edit Distance No-Damage Decay Quality >= 0.6, Read Mapping Ratio >= 0.5 | Z5: 0.4718 | AA5: 0.5031 | AB5: 0 | AC5: 0.7028 | AD5: =VLOOKUP(A5,AE:AE,1,FALSE) -> #REF!
A6: LL157 | B6: Fusobacterium necrophorum | D6: bowtie2 | E6: TRUE | F6: 57 | G6: 9.058268 | H6: 0.0011931368 | I6: TRUE | J6: 0 | K6: FALSE | L6: 73 | M6: 1.2807 | N6: 0.0014X | O6: 0.13% | P6: 43.05 | Q6: 39 | R6: 0.083333 | S6: 0.4144 | T6: 0.9036 | U6: 98.35% | V6: 0 | W6: #3 | X6: 6/10 | Y6: E-value > 0.001, Reads >= 50, ANI > 96.5%, 5' C>T Damage >= 0.01, Breadth Ratio >= 0.8, Read Mapping Ratio >= 0.5 | Z6: 0.4008 | AA6: 0.4144 | AB6: 0 | AC6: 0.1961 | AD6: =VLOOKUP(A6,AE:AE,1,FALSE) -> #REF!
A7: LL158 | B7: Bibersteinia trehalosi | D7: bowtie2 | E7: TRUE | F7: 168 | G7: 14.692433 | H7: 0.01173587 | I7: TRUE | J7: 0 | K7: FALSE | L7: 130 | M7: 0.7738 | N7: 0.0028X | O7: 0.24% | P7: 50 | Q7: 42 | R7: 0 | S7: 0.4699 | T7: 0.8718 | U7: 99.05% | V7: 0 | W7: #1 | X7: 7/10 | Y7: E-value > 0.001, Reads >= 50, ANI > 96.5%, Breadth Ratio >= 0.8, Edit Distance No-Damage Decay Quality >= 0.6, Genus Ranking = 1, Read Mapping Ratio >= 0.5 | Z7: 0.4545 | AA7: 0.4699 | AB7: 0 | AC7: 0.7607 | AD7: =VLOOKUP(A7,AE:AE,1,FALSE) -> #REF!
A8: LL159 | B8: Mannheimia haemolytica | D8: bowtie2 | E8: TRUE | F8: 78 | G8: 6.4560464 | H8: 0.0015509167 | I8: TRUE | J8: 0 | K8: FALSE | L8: 177 | M8: 2.2692 | N8: 0.0028X | O8: 0.24% | P8: 44.03 | Q8: 39 | R8: 0.029412 | S8: 0.555 | T8: 0.8652 | U8: 98.70% | V8: 0 | W8: #2 | X8: 7/10 | Y8: E-value > 0.001, Reads >= 50, ANI > 96.5%, 5' C>T Damage >= 0.01, Breadth Ratio >= 0.8, Edit Distance No-Damage Decay Quality >= 0.6, Read Mapping Ratio >= 0.5 | Z8: 0.4794 | AA8: 0.555 | AB8: 0 | AC8: 0.6384 | AD8: =VLOOKUP(A8,AE:AE,1,FALSE) -> #REF!
A9: LL159 | B9: Bibersteinia trehalosi | D9: bowtie2 | E9: TRUE | F9: 169 | G9: 11.418397 | H9: 0.0071427077 | I9: TRUE | J9: 0 | K9: FALSE | L9: 170 | M9: 1.0059 | N9: 0.0034X | O9: 0.29% | P9: 46.6 | Q9: 41 | R9: 0 | S9: 0.5493 | T9: 0.868 | U9: 98.78% | V9: 0.875 | W9: #1 | X9: 8/10 | Y9: E-value > 0.001, Reads >= 50, ANI > 96.5%, Breadth Ratio >= 0.8, Edit Distance Damage Decay Quality >= 0.5, Edit Distance No-Damage Decay Quality >= 0.6, Genus Ranking = 1, Read Mapping Ratio >= 0.5 | Z9: 0.4819 | AA9: 0.5493 | AB9: 0.875 | AC9: 0.7182 | AD9: =VLOOKUP(A9,AE:AE,1,FALSE) -> #REF!
A10: LL159 | B10: Fusobacterium nucleatum | D10: bowtie2 | E10: TRUE | F10: 416 | G10: 8.8935845 | H10: 0.0034231269 | I10: TRUE | J10: 0 | K10: FALSE | L10: 136 | M10: 0.3269 | N10: 0.003X | O10: 0.29% | P10: 47.33 | Q10: 42 | R10: 0.055556 | S10: 0.6221 | T10: 0.9847 | U10: 98.40% | V10: 0 | W10: #1 | X10: 6/10 | Y10: E-value > 0.001, Reads >= 50, ANI > 96.5%, 5' C>T Damage >= 0.01, Breadth Ratio >= 0.8, Genus Ranking = 1 | Z10: 0.4883 | AA10: 0.6221 | AB10: 0 | AC10: 0.2266 | AD10: =VLOOKUP(A10,AE:AE,1,FALSE) -> #REF!
A11: LL159 | B11: Fusobacterium necrophorum | D11: bowtie2 | E11: TRUE | F11: 110 | G11: 13.177532 | H11: 0.0048632355 | I11: TRUE | J11: 0 | K11: FALSE | L11: 86 | M11: 0.7818 | N11: 0.0018X | O11: 0.18% | P11: 45.77 | Q11: 41 | R11: 0 | S11: 0.5728 | T11: 0.9917 | U11: 99.19% | W11: #2 | X11: 5/9 | Y11: E-value > 0.001, Reads >= 50, ANI > 96.5%, Breadth Ratio >= 0.8, Read Mapping Ratio >= 0.5 | Z11: 0.4425 | AA11: 0.5728 | AC11: 0.8181 | AD11: =VLOOKUP(A11,AE:AE,1,FALSE) -> #REF!
A12: LL160 | B12: Capnocytophaga canimorsus | D12: bowtie2 | E12: TRUE | F12: 523 | G12: 3.3637136 | H12: 0.0013034019 | I12: TRUE | J12: 0 | K12: FALSE | L12: 87 | M12: 0.1663 | N12: 0.0015X | O12: 0.05% | P12: 40.49 | Q12: 39 | R12: 0 | S12: 0.2091 | T12: 0.3576 | U12: 98.75% | V12: 0 | W12: #1 | X12: 5/10 | Y12: E-value > 0.001, Reads >= 50, ANI > 96.5%, Edit Distance No-Damage Decay Quality >= 0.6, Genus Ranking = 1 | Z12: 0.2508 | AA12: 0.2091 | AB12: 0 | AC12: 0.7132 | AD12: =VLOOKUP(A12,AE:AE,1,FALSE) -> #REF!
A13: LL160 | B13: Mannheimia haemolytica | D13: bowtie2 | E13: TRUE | F13: 116 | G13: 7.4282076 | H13: 0.0030492931 | I13: TRUE | J13: 0 | K13: FALSE | L13: 123 | M13: 1.0603 | N13: 0.0023X | O13: 0.18% | P13: 52.29 | Q13: 45 | R13: 0.045455 | S13: 0.4357 | T13: 0.7666 | U13: 98.74% | V13: 0.87 | W13: #1 | X13: 7/10 | Y13: E-value > 0.001, Reads >= 50, ANI > 96.5%, 5' C>T Damage >= 0.01, Edit Distance Damage Decay Quality >= 0.5, Genus Ranking = 1, Read Mapping Ratio >= 0.5 | Z13: 0.4274 | AA13: 0.4357 | AB13: 0.87 | AC13: 0.2601 | AD13: =VLOOKUP(A13,AE:AE,1,FALSE) -> #REF!
A14: LL160 | B14: Streptococcus pyogenes | D14: bowtie2 | E14: TRUE | F14: 315 | G14: 8.7106785 | H14: 0.0039375048 | I14: TRUE | J14: 0 | K14: FALSE | L14: 10 | M14: 0.0317 | N14: 0.0002X | O14: 0.02% | P14: 36.5 | Q14: 36.5 | R14: 0 | S14: 0.3084 | T14: 1.0001 | U14: 98.36% | W14: #6 | X14: 4/9 | Y14: E-value > 0.001, Reads >= 50, ANI > 96.5%, Breadth Ratio >= 0.8 | Z14: 0.2357 | AA14: 0.3084 | AC14: 0.1028 | AD14: =VLOOKUP(A14,AE:AE,1,FALSE) -> #REF!
A15: LL160 | B15: Clostridioides difficile | D15: bowtie2 | E15: TRUE | F15: 182 | G15: 8.0268438 | H15: 0.001030022 | I15: TRUE | J15: 0 | K15: FALSE | L15: 30 | M15: 0.1648 | N15: 0.0003X | O15: 0.02% | P15: 40.17 | Q15: 41 | R15: 0 | S15: 0.2654 | T15: 0.6159 | U15: 99.00% | W15: #1 | X15: 4/9 | Y15: E-value > 0.001, Reads >= 50, ANI > 96.5%, Genus Ranking = 1 | Z15: 0.2597 | AA15: 0.2654 | AC15: 0.718 | AD15: =VLOOKUP(A15,AE:AE,1,FALSE) -> #REF!
A16: LL160 | B16: Fusobacterium nucleatum | D16: bowtie2 | E16: TRUE | F16: 11286 | G16: 7.7871102 | H16: 0.065751392 | I16: TRUE | J16: 0 | K16: FALSE | L16: 3484 | M16: 0.3087 | N16: 0.082X | O16: 6.1% | P16: 51.32 | Q16: 45 | R16: 0.026379 | S16: 0.8756 | T16: 0.7744 | U16: 98.36% | V16: 0.8697 | W16: #2 | X16: 6/10 | Y16: E-value > 0.001, Reads >= 50, ANI > 96.5%, 5' C>T Damage >= 0.01, Entropy (1000bp) >= 0.8 (bacteria), Edit Distance Damage Decay Quality >= 0.5 | Z16: 0.7644 | AA16: 0.8756 | AB16: 0.8697 | AC16: 0.2092 | AD16: =VLOOKUP(A16,AE:AE,1,FALSE) -> #REF!
A17: LL160 | B17: Fusobacterium necrophorum | D17: bowtie2 | E17: TRUE | F17: 23851 | G17: 29.963722 | H17: 1.9528035 | I17: TRUE | J17: 0 | K17: FALSE | L17: 20984 | M17: 0.8798 | N17: 0.5175X | O17: 38.23% | P17: 54.02 | Q17: 48 | R17: 0.026477 | S17: 0.9735 | T17: 0.9464 | U17: 99.57% | V17: 0.8851 | W17: #1 | X17: 10/10 | Y17: E-value > 0.001, Reads >= 50, ANI > 96.5%, 5' C>T Damage >= 0.01, Breadth Ratio >= 0.8, Entropy (1000bp) >= 0.8 (bacteria), Edit Distance Damage Decay Quality >= 0.5, Edit Distance No-Damage Decay Quality >= 0.6, Genus Ranking = 1, Read Mapping Ratio >= 0.5 | Z17: 0.9295 | AA17: 0.9735 | AB17: 0.8851 | AC17: 0.8661 | AD17: =VLOOKUP(A17,AE:AE,1,FALSE) -> #REF!
A18: LL161 | B18: Capnocytophaga canimorsus | D18: bowtie2 | E18: TRUE | F18: 92 | G18: 13.005347 | H18: 0.0034317283 | I18: TRUE | J18: 0 | K18: FALSE | L18: 15 | M18: 0.163 | N18: 0.0003X | O18: 0.02% | P18: 49.33 | Q18: 39 | R18: 0 | S18: 0.2409 | T18: 0.7366 | U18: 97.84% | V18: 0 | W18: #1 | X18: 4/10 | Y18: E-value > 0.001, Reads >= 50, ANI > 96.5%, Genus Ranking = 1 | Z18: 0.2409 | AA18: 0.2409 | AB18: 0 | AC18: 0.0866 | AD18: =VLOOKUP(A18,AE:AE,1,FALSE) -> #REF!
A19: LL161 | B19: Bibersteinia trehalosi | D19: bowtie2 | E19: TRUE | F19: 366 | G19: 13.347923 | H19: 0.02094609 | I19: TRUE | J19: 0 | K19: FALSE | L19: 258 | M19: 0.7049 | N19: 0.0063X | O19: 0.47% | P19: 57.06 | Q19: 45 | R19: 0 | S19: 0.5033 | T19: 0.7442 | U19: 98.91% | V19: 0.8812 | W19: #1 | X19: 7/10 | Y19: E-value > 0.001, Reads >= 50, ANI > 96.5%, Edit Distance Damage Decay Quality >= 0.5, Edit Distance No-Damage Decay Quality >= 0.6, Genus Ranking = 1, Read Mapping Ratio >= 0.5 | Z19: 0.5014 | AA19: 0.5033 | AB19: 0.8812 | AC19: 0.7058 | AD19: =VLOOKUP(A19,AE:AE,1,FALSE) -> #REF!
A20: LL161 | B20: Streptococcus pyogenes | D20: bowtie2 | E20: TRUE | F20: 188 | G20: 6.4635763 | H20: 0.0012973011 | I20: TRUE | J20: 0 | K20: FALSE | L20: 121 | M20: 0.6436 | N20: 0.0034X | O20: 0.21% | P20: 48.68 | Q20: 40 | R20: 0 | S20: 0.4749 | T20: 0.6283 | U20: 98.64% | V20: 0 | W20: #10 | X20: 4/10 | Y20: E-value > 0.001, Reads >= 50, ANI > 96.5%, Read Mapping Ratio >= 0.5 | Z20: 0.4215 | AA20: 0.4749 | AB20: 0 | AC20: 0.2751 | AD20: =VLOOKUP(A20,AE:AE,1,FALSE) -> #REF!
A21: LL161 | B21: Fusobacterium nucleatum | D21: bowtie2 | E21: TRUE | F21: 265 | G21: 11.23911 | H21: 0.0034846302 | I21: TRUE | J21: 0 | K21: FALSE | L21: 59 | M21: 0.2226 | N21: 0.0014X | O21: 0.14% | P21: 52.14 | Q21: 49 | R21: 0 | S21: 0.5017 | T21: 0.9812 | U21: 98.31% | V21: 0 | W21: #1 | X21: 5/10 | Y21: E-value > 0.001, Reads >= 50, ANI > 96.5%, Breadth Ratio >= 0.8, Genus Ranking = 1 | Z21: 0.4035 | AA21: 0.5017 | AB21: 0 | AC21: 0.179 | AD21: =VLOOKUP(A21,AE:AE,1,FALSE) -> #REF!
A22: LL161 | B22: Fusobacterium necrophorum | D22: bowtie2 | E22: TRUE | F22: 231 | G22: 15.765794 | H22: 0.014541673 | I22: TRUE | J22: 0 | K22: FALSE | L22: 181 | M22: 0.7835 | N22: 0.0042X | O22: 0.4% | P22: 50.36 | Q22: 44 | R22: 0 | S22: 0.6302 | T22: 0.9731 | U22: 99.25% | V22: 0 | W22: #2 | X22: 6/10 | Y22: E-value > 0.001, Reads >= 50, ANI > 96.5%, Breadth Ratio >= 0.8, Edit Distance No-Damage Decay Quality >= 0.6, Read Mapping Ratio >= 0.5 | Z22: 0.5122 | AA22: 0.6302 | AB22: 0 | AC22: 0.8484 | AD22: =VLOOKUP(A22,AE:AE,1,FALSE) -> #REF!
A23: LL163 | B23: Capnocytophaga canimorsus | D23: bowtie2 | E23: TRUE | F23: 221 | G23: 5.5500797 | H23: 0.0015010407 | I23: TRUE | J23: 0 | K23: FALSE | L23: 94 | M23: 0.4253 | N23: 0.0016X | O23: 0.06% | P23: 42.01 | Q23: 39 | R23: 0.0625 | S23: 0.224 | T23: 0.391 | U23: 98.81% | V23: 0 | W23: #1 | X23: 6/10 | Y23: E-value > 0.001, Reads >= 50, ANI > 96.5%, 5' C>T Damage >= 0.01, Edit Distance No-Damage Decay Quality >= 0.6, Genus Ranking = 1 | Z23: 0.2918 | AA23: 0.224 | AB23: 0 | AC23: 0.726 | AD23: =VLOOKUP(A23,AE:AE,1,FALSE) -> #REF!
A24: LL163 | B24: Mannheimia haemolytica | D24: bowtie2 | E24: TRUE | F24: 243 | G24: 7.5496047 | H24: 0.0065689296 | I24: TRUE | J24: 0 | K24: FALSE | L24: 579 | M24: 2.3827 | N24: 0.0092X | O24: 0.69% | P24: 43.63 | Q24: 39 | R24: 0.009615 | S24: 0.6446 | T24: 0.7591 | U24: 98.60% | V24: 0 | W24: #1 | X24: 5/10 | Y24: E-value > 0.001, Reads >= 50, ANI > 96.5%, Genus Ranking = 1, Read Mapping Ratio >= 0.5 | Z24: 0.5738 | AA24: 0.6446 | AB24: 0 | AC24: 0.2609 | AD24: =VLOOKUP(A24,AE:AE,1,FALSE) -> #REF!
A25: LL163 | B25: Bibersteinia trehalosi | D25: bowtie2 | E25: TRUE | F25: 1912 | G25: 13.842706 | H25: 0.11046525 | I25: TRUE | J25: 0 | K25: FALSE | L25: 1769 | M25: 0.9252 | N25: 0.0352X | O25: 3.02% | P25: 46.54 | Q25: 42 | R25: 0.00838 | S25: 0.828 | T25: 0.8746 | U25: 99.16% | V25: 0.8889 | W25: #1 | X25: 9/10 | Y25: E-value > 0.001, Reads >= 50, ANI > 96.5%, Breadth Ratio >= 0.8, Entropy (1000bp) >= 0.8 (bacteria), Edit Distance Damage Decay Quality >= 0.5, Edit Distance No-Damage Decay Quality >= 0.6, Genus Ranking = 1, Read Mapping Ratio >= 0.5 | Z25: 0.7089 | AA25: 0.828 | AB25: 0.8889 | AC25: 0.8425 | AD25: =VLOOKUP(A25,AE:AE,1,FALSE) -> #REF!
A26: LL163 | B26: Streptococcus pyogenes | D26: bowtie2 | E26: TRUE | F26: 334 | G26: 4.8354323 | H26: 0.0012889512 | I26: TRUE | J26: 0 | K26: FALSE | L26: 354 | M26: 1.0599 | N26: 0.0082X | O26: 0.43% | P26: 40.58 | Q26: 38 | R26: 0.014706 | S26: 0.5335 | T26: 0.53 | U26: 98.54% | V26: 0 | W26: #10 | X26: 5/10 | Y26: E-value > 0.001, Reads >= 50, ANI > 96.5%, 5' C>T Damage >= 0.01, Read Mapping Ratio >= 0.5 | Z26: 0.483 | AA26: 0.5335 | AB26: 0 | AC26: 0.264 | AD26: =VLOOKUP(A26,AE:AE,1,FALSE) -> #REF!
A27: LL163 | B27: Streptococcus agalactiae | D27: bowtie2 | E27: TRUE | F27: 184 | G27: 4.8671653 | H27: 0.001791887 | I27: TRUE | J27: 0 | K27: FALSE | L27: 369 | M27: 2.0054 | N27: 0.0077X | O27: 0.45% | P27: 43.14 | Q27: 39 | R27: 0.036145 | S27: 0.54 | T27: 0.5923 | U27: 98.42% | V27: 0.8885 | W27: #15 | X27: 6/10 | Y27: E-value > 0.001, Reads >= 50, ANI > 96.5%, 5' C>T Damage >= 0.01, Edit Distance Damage Decay Quality >= 0.5, Read Mapping Ratio >= 0.5 | Z27: 0.4892 | AA27: 0.54 | AB27: 0.8885 | AC27: 0.2379 | AD27: =VLOOKUP(A27,AE:AE,1,FALSE) -> #REF!
... A30: LL163 | B30: Fusobacterium necrophorum | D30: bowtie2 | E30: TRUE | F30: 13248 | G30: 25.326919 | H30: 1.1916994 | I30: TRUE | J30: 0 | K30: FALSE | L30: 12846 | M30: 0.9697 | N30: 0.3129X | O30: 25.19% | P30: 53.34 | Q30: 46 | R30: 0.015476 | S30: 0.9614 | T30: 0.9379 | U30: 99.52% | V30: 0.8837 | W30: #1 | X30: 10/10 | Y30: E-value > 0.001, Reads >= 50, ANI > 96.5%, 5' C>T Damage >= 0.01, Breadth Ratio >= 0.8, Entropy (1000bp) >= 0.8 (bacteria), Edit Distance Damage Decay Quality >= 0.5, Edit Distance No-Damage Decay Quality >= 0.6, Genus Ranking = 1, Read Mapping Ratio >= 0.5 | Z30: 0.8953 | AA30: 0.9614 | AB30: 0.8837 | AC30: 0.8445 | AD30: =VLOOKUP(A30,AE:AE,1,FALSE) -> #REF!
A31: YG01 | B31: Sheeppox virus | D31: bowtie2 | E31: TRUE | F31: 1 | G31: 30.06598 | H31: 0.013956 | I31: TRUE | J31: 0 | K31: FALSE | L31: 3 | M31: 3 | N31: 0.0012X | O31: 0.12% | P31: 58 | Q31: 58 | R31: 0 | S31: 0.2193 | T31: 1.0006 | U31: 99.43% | W31: #1 | X31: 6/9 | Y31: E-value > 0.001, Reads >= 1, ANI > 96.5%, Breadth Ratio >= 0.8, Genus Ranking = 1, Read Mapping Ratio >= 0.5 | Z31: 0.1502 | AA31: 0.2193 | AC31: 0.8193 | AD31: =VLOOKUP(A31,AE:AE,1,FALSE) -> #REF!
A32: YG01 | B32: Molluscum contagiosum virus | D32: bowtie2 | E32: TRUE | F32: 7 | G32: 21.762711 | H32: 0.010242629 | I32: TRUE | J32: 0 | K32: FALSE | L32: 3 | M32: 0.4286 | N32: 0.0007X | O32: 0.07% | P32: 47.33 | Q32: 52 | R32: 0 | S32: 0.2092 | T32: 1.0004 | U32: 100.00% | X32: 4/9 | Y32: E-value > 0.001, Reads >= 5, ANI > 96.5%, Breadth Ratio >= 0.8 | Z32: 0.1455 | AA32: 0.2092 | AC32: 0 | AD32: =VLOOKUP(A32,AE:AE,1,FALSE) -> #REF!
A33: YG01 | B33: Escherichia coli | D33: bowtie2 | E33: TRUE | F33: 633 | G33: 16.735057 | H33: 0.0027725008 | I33: TRUE | J33: 0 | K33: FALSE | L33: 3795 | M33: 5.9953 | N33: 0.0448X | O33: 4.34% | P33: 66.1 | Q33: 57 | R33: 0.014847 | S33: 0.8955 | T33: 0.9895 | U33: 99.01% | V33: 0.8657 | W33: #1 | X33: 9/10 | Y33: E-value > 0.001, Reads >= 100, ANI > 96.5%, 5' C>T Damage >= 0.01, Breadth Ratio >= 0.8, Entropy (1000bp) >= 0.8 (bacteria), Edit Distance Damage Decay Quality >= 0.5, Genus Ranking = 1, Read Mapping Ratio >= 0.5 | Z33: 0.7493 | AA33: 0.8955 | AB33: 0.8657 | AC33: 0.4222 | AD33: =VLOOKUP(A33,AE:AE,1,FALSE) -> #REF!
A34: YG01 | B34: Staphylococcus aureus | D34: bowtie2 | E34: TRUE | F34: 2187 | G34: 10.269371 | H34: 0.015447181 | I34: TRUE | J34: 0 | K34: FALSE | L34: 546 | M34: 0.2497 | N34: 0.0136X | O34: 1.15% | P34: 70.09 | Q34: 57 | R34: 0.018519 | S34: 0.7109 | T34: 0.8557 | U34: 98.75% | V34: 0.6501 | W34: #9 | X34: 6/10 | Y34: E-value > 0.001, Reads >= 200, ANI > 96.5%, 5' C>T Damage >= 0.01, Breadth Ratio >= 0.8, Edit Distance Damage Decay Quality >= 0.5 | Z34: 0.5833 | AA34: 0.7109 | AB34: 0.6501 | AC34: 0.2339 | AD34: =VLOOKUP(A34,AE:AE,1,FALSE) -> #REF!
A35: YG01 | B35: Streptococcus pneumoniae | D35: bowtie2 | E35: TRUE | F35: 729 | G35: 18.802791 | H35: 0.034482579 | I35: TRUE | J35: 0 | K35: FALSE | L35: 1074 | M35: 1.4733 | N35: 0.0339X | O35: 3.23% | P35: 66.63 | Q35: 54.5 | R35: 0.004878 | S35: 0.845 | T35: 0.9682 | U35: 98.65% | V35: 0.8147 | W35: #4 | X35: 7/10 | Y35: E-value > 0.001, Reads >= 50, ANI > 96.5%, Breadth Ratio >= 0.8, Entropy (1000bp) >= 0.8 (bacteria), Edit Distance Damage Decay Quality >= 0.5, Read Mapping Ratio >= 0.5 | Z35: 0.6912 | AA35: 0.845 | AB35: 0.8147 | AC35: 0.2423 | AD35: =VLOOKUP(A35,AE:AE,1,FALSE) -> #REF!
A36: YG01 | B36: Listeria monocytogenes | D36: bowtie2 | E36: TRUE | F36: 98 | G36: 17.031295 | H36: 0.0023045633 | I36: TRUE | J36: 0 | K36: FALSE | L36: 8 | M36: 0.0816 | N36: 0.0001X | O36: 0.01% | P36: 38.62 | Q36: 37.5 | R36: 0 | S36: 0.2386 | T36: 0.9191 | U36: 97.73% | V36: 0 | W36: #1 | X36: 5/10 | Y36: E-value > 0.001, Reads >= 50, ANI > 96.5%, Breadth Ratio >= 0.8, Genus Ranking = 1 | Z36: 0.1852 | AA36: 0.2386 | AB36: 0 | AC36: 0 | AD36: =VLOOKUP(A36,AE:AE,1,FALSE) -> #REF!
A37: YG01 | B37: Erysipelothrix rhusiopathiae | C37: Cow | D37: bowtie2 | E37: TRUE | F37: 32896 | G37: 91.600128 | H37: 6.7711199 | I37: TRUE | J37: 0 | K37: FALSE | L37: 32927 | M37: 1.0009 | N37: 1.3156X | O37: 69.72% | P37: 70.74 | Q37: 62 | R37: 0.010357 | S37: 0.9872 | T37: 0.9529 | U37: 99.48% | V37: 0.8647 | W37: #1 | X37: 10/10 | Y37: E-value > 0.001, Reads >= 50, ANI > 96.5%, 5' C>T Damage >= 0.01, Breadth Ratio >= 0.8, Entropy (1000bp) >= 0.8 (bacteria), Edit Distance Damage Decay Quality >= 0.5, Edit Distance No-Damage Decay Quality >= 0.6, Genus Ranking = 1, Read Mapping Ratio >= 0.5 | Z37: 0.9625 | AA37: 0.9872 | AB37: 0.8647 | AC37: 0.8287 | AD37: =VLOOKUP(A37,AE:AE,1,FALSE) -> #REF!
A38: YG01 | B38: Streptococcus pyogenes | D38: bowtie2 | E38: TRUE | F38: 107 | G38: 27.239401 | H38: 0.013077847 | I38: TRUE | J38: 0 | K38: FALSE | L38: 110 | M38: 1.028 | N38: 0.0039X | O38: 0.38% | P38: 61.77 | Q38: 53 | R38: 0 | S38: 0.6053 | T38: 0.9841 | U38: 98.94% | V38: 0.3 | W38: #19 | X38: 6/10 | Y38: E-value > 0.001, Reads >= 50, ANI > 96.5%, Breadth Ratio >= 0.8, Edit Distance No-Damage Decay Quality >= 0.6, Read Mapping Ratio >= 0.5 | Z38: 0.4769 | AA38: 0.6053 | AB38: 0.3 | AC38: 0.7028 | AD38: =VLOOKUP(A38,AE:AE,1,FALSE) -> #REF!
A39: YG01 | B39: Streptococcus equinus | D39: bowtie2 | E39: TRUE | F39: 265 | G39: 24.183574 | H39: 0.072705094 | I39: TRUE | J39: 0 | K39: FALSE | L39: 368 | M39: 1.3887 | N39: 0.0136X | O39: 1.34% | P39: 71.84 | Q39: 58.5 | R39: 0.0125 | S39: 0.7497 | T39: 0.9883 | U39: 98.77% | V39: 0.55 | W39: #10 | X39: 8/10 | Y39: E-value > 0.001, Reads >= 50, ANI > 96.5%, 5' C>T Damage >= 0.01, Breadth Ratio >= 0.8, Edit Distance Damage Decay Quality >= 0.5, Edit Distance No-Damage Decay Quality >= 0.6, Read Mapping Ratio >= 0.5 | Z39: 0.5959 | AA39: 0.7497 | AB39: 0.55 | AC39: 0.6094 | AD39: =VLOOKUP(A39,AE:AE,1,FALSE) -> #REF!
A40: YG01 | B40: Streptococcus gallolyticus | D40: bowtie2 | E40: TRUE | F40: 57 | G40: 17.902538 | H40: 0.0090709158 | I40: TRUE | J40: 0 | K40: FALSE | L40: 218 | M40: 3.8246 | N40: 0.0066X | O40: 0.64% | P40: 68.27 | Q40: 57 | R40: 0 | S40: 0.668 | T40: 0.9814 | U40: 98.84% | V40: 0.8193 | W40: #25 | X40: 6/10 | Y40: E-value > 0.001, Reads >= 50, ANI > 96.5%, Breadth Ratio >= 0.8, Edit Distance Damage Decay Quality >= 0.5, Read Mapping Ratio >= 0.5 | Z40: 0.5324 | AA40: 0.668 | AB40: 0.8193 | AC40: 0.5907 | AD40: =VLOOKUP(A40,AE:AE,1,FALSE) -> #REF!
A41: YG01 | B41: Clostridium perfringens | D41: bowtie2 | E41: TRUE | F41: 387 | G41: 38.366682 | H41: 0.038159316 | I41: TRUE | J41: 0 | K41: FALSE | L41: 237 | M41: 0.6124 | N41: 0.0057X | O41: 0.56% | P41: 80.31 | Q41: 68 | R41: 0 | S41: 0.6662 | T41: 0.9939 | U41: 99.02% | V41: 0.55 | W41: #2 | X41: 7/10 | Y41: E-value > 0.001, Reads >= 50, ANI > 96.5%, Breadth Ratio >= 0.8, Edit Distance Damage Decay Quality >= 0.5, Edit Distance No-Damage Decay Quality >= 0.6, Read Mapping Ratio >= 0.5 | Z41: 0.5255 | AA41: 0.6662 | AB41: 0.55 | AC41: 0.7884 | AD41: =VLOOKUP(A41,AE:AE,1,FALSE) -> #REF!
A42: YG01 | B42: Fusobacterium nucleatum | D42: bowtie2 | E42: TRUE | F42: 316 | G42: 23.305685 | H42: 0.017790006 | I42: TRUE | J42: 0 | K42: FALSE | L42: 101 | M42: 0.3196 | N42: 0.0033X | O42: 0.32% | P42: 71.38 | Q42: 60 | R42: 0.125 | S42: 0.5872 | T42: 0.9679 | U42: 98.54% | V42: 0.3673 | W42: #1 | X42: 7/10 | Y42: E-value > 0.001, Reads >= 50, ANI > 96.5%, 5' C>T Damage >= 0.01, Breadth Ratio >= 0.8, Edit Distance No-Damage Decay Quality >= 0.6, Genus Ranking = 1 | Z42: 0.4546 | AA42: 0.5872 | AB42: 0.3673 | AC42: 0.6806 | AD42: =VLOOKUP(A42,AE:AE,1,FALSE) -> #REF!
...

Sheet S6  Pathogens Hits passing dete
A1: Sample | B1: Pathogen | C1: host_species | D1: Basic_taxon_name | E1: samp_taxon_common | F1: tissue_clean | G1: tissue_type | H1: Krakenuniq_reads | I1: Guellil_et_al_Evalue | J1: score_num | K1: sample_age | L1: sample_age_lower | M1: sample_age_upper | N1: Relative_entropy | O1: Genus_ranking | P1: Edit_distance_decay_quality_no_damage | Q1: Breadth_ratio | R1: ANI_num | S1: mapping_ratio | T1: latitude | U1: longitude | V1: geo_loc_name | W1: site_name | X1: pass_filter
A2: AA401 | B2: Clostridium perfringens | C2: Sus | D2: Sus | E2: Pig | F2: missing | G2: missing | H2: 296 | I2: 0.0068997081 | J2: 9 | K2: 1065 | L2: 846 | M2: 966 | N2: 0.6616 | O2: #1 | P2: 0.821 | Q2: 1.0013 | R2: 99.03 | S2: 0.7703 | T2: 65.4854 | U2: -19.3016 | V2: Iceland | W2: Skagafjordur | X2: TRUE
A3: AA401 | B3: Erysipelothrix rhusiopathiae | C3: Sus | D3: Sus | E3: Pig | F3: missing | G3: missing | H3: 428 | I3: 0.096038808 | J3: 9 | K3: 1065 | L3: 846 | M3: 966 | N3: 0.781 | O3: #1 | P3: 0.8426 | Q3: 0.9917 | R3: 99.23 | S3: 0.972 | T3: 65.4854 | U3: -19.3016 | V3: Iceland | W3: Skagafjordur | X3: TRUE
A4: AA478 | B4: Clostridium perfringens | C4: Sus | D4: Sus | E4: Wild boar/pig | F4: missing | G4: missing | H4: 911 | I4: 0.016888782 | J4: 9 | K4: 7000 | L4: NA | M4: NA | N4: 0.763 | O4: #1 | P4: 0.72 | Q4: 0.9947 | R4: 98.65 | S4: 0.6235 | T4: 45.0144 | U4: 34.1821 | V4: Ukraine | W4: Buran-Kaya IV | X4: TRUE
A5: AL725 | B5: Erysipelothrix rhusiopathiae | C5: Sus | D5: Sus | E5: Wild boar | F5: missing | G5: missing | H5: 82 | I5: 0.015600732 | J5: 9 | K5: 10200 | L5: 10000 | M5: 10300 | N5: 0.583 | O5: #1 | P5: 0.8466 | Q5: 1.0014 | R5: 99.32 | S5: 0.9878 | T5: 38.34935 | U5: 34.230237 | V5: Turkey | W5: Aşıklı Höyük | X5: TRUE
